<?xml version="1.0"?>
<robot name="trikey_light">
    <link name="base_footprint">
        
    </link>
    
    <link name="shaft_link">
        <inertial>
            <origin xyz="0.0 0.0 0.0" rpy="0.0 0.0 0.0"/>
            <mass value="1.0"/>
            <inertia ixx="1.333" ixy="0.0" ixz="0.0" iyy="0.0" iyz="0.0" izz="1.333"/>
        </inertial>
        <visual name="">
            <origin xyz="0.0 1.2 1.0" rpy="1.57 0.0 0.0"/>
            <geometry>
                <cylinder radius = "0.5" length = "2"/>
            </geometry>
            <material name="red">
                <color rgba="1.0 0.0 0.0 1.0"/>
                <texture filename=""/>
            </material>
        </visual>
        <collision>
            <origin xyz="0.0 0.0 0.0" rpy="0.0 0.0 0.0"/>
            <geometry> 
                <cylinder radius = "0.5" length = "2"/>
            </geometry>
        </collision>
    </link>                                      
    <joint name="base_joint" type="fixed">
        <origin xyz="0.0 0.0 0.0" rpy="0.0 0.0 0.0"/>
        <parent link="base_footprint"/>
        <child link="shaft_link"/>
        <limit lower="0.0" upper="0.0" effort="0.0" velocity="0.0"/>
    </joint>

    <!-- wheel -->

    <link name="wheel_link"> 
        <inertial>
            <origin xyz="0.0 0.0 0.0" rpy="0.0 0.0 0.0"/>
            <mass value="0.5"/>
            <inertia ixx="0.5" ixy="0.0" ixz="0.0" iyy="0.25" iyz="0.0" izz="0.5"/>
        </inertial>
        <visual name="">
            <origin xyz="0.0 0.0 -0.2" rpy="0.0 0.0 0.0"/>
            <geometry>
                <cylinder radius="1.0" length="0.3"/>
            </geometry>
            <material name="red">
                <color rgba="1.0 0.0 0.0 1.0"/>
                <texture filename=""/>
            </material>
        </visual>
        <collision>
            <origin xyz="0.0 0.0 0.0" rpy="0.0 0.0 0.0"/>
            <geometry>
                <cylinder radius="1.0" length="0.3"/>
            </geometry>
        </collision>
    </link>

    <joint name="wheel_joint" type="continuous">
        <origin xyz="0.0 2.0 1.0" rpy="1.57 0.0 0.0"/>
        <parent link="shaft_link"/>
        <child link="wheel_link"/>
        <axis xyz="0.0 0.0 1.0"/>
        <limit effort="10.0" velocity="5.0"/>
    </joint>
    
    <transmission name="wheel_joint_transmission">
        <type>transmission_interface/SimpleTransmission</type>
        <joint name="wheel_joint">
            <hardwareInterface>hardware_interface/EffortJointInterface</hardwareInterface>
        </joint>
        <actuator name="wheel_motor">
            <hardwareInterface>hardware_interface/EffortJointInterface</hardwareInterface>
            <mechanicalReduction>1</mechanicalReduction>
        </actuator>
    </transmission>

    <gazebo>
        <plugin name="gazebo_ros_control" filename="libgazebo_ros_control.so">
            <robotNamespace>/trikey_light</robotNamespace>
        </plugin>
    </gazebo>

</robot>