<?xml version="1.0"?>
<robot xmlns:xacro="http://www.ros.org/wiki/xacro"  name="trikey_light">

   <!-- Central Body -->
    <link name="center_link">
        <!-- <inertial>
            <origin xyz="0.0 0.0 1.0" rpy="0.0 0.0 0.0"/>
            <mass value="3.0"/>
            <inertia ixx="2.0" ixy="0.0" ixz="0.0" iyy="2.0" iyz="0.0" izz="2.0"/>
        </inertial> -->
        <visual>
            <origin xyz="0.0 0.0 1.0" rpy="0.0 0.0 0.0"/>
            <geometry>
                <cylinder radius="0.6" length="0.5"/>
            </geometry>
            <material name="gray">
                <color rgba="0.5 0.5 0.5 1.0"/>
            </material>
        </visual>
        <collision>
            <origin xyz="0.0 0.0 1.0" rpy="0.0 0.0 0.0"/>
            <geometry>
                <cylinder radius="0.6" length="0.5"/>
            </geometry>
        </collision>
    </link>
  <xacro:macro name="shaft_wheel" params="id x y rpy">
    <!-- Shaft -->
    <link name="shaft_link_${id}">
      <inertial>
        <origin xyz="0.0 1.2 1.0" rpy="1.5708 0.0 0.0"/>
        <mass value="1.0"/>
        <inertia ixx="1.333" ixy="0.0" ixz="0.0" iyy="0.0" iyz="0.0" izz="1.333"/>
      </inertial>
      <visual>
        <origin xyz="0.0 1.2 1.0" rpy="1.5708 0.0 0.0"/>
        <geometry>
          <cylinder radius="0.5" length="2"/>
        </geometry>
        <material name="red">
          <color rgba="1.0 0.0 0.0 1.0"/>
        </material>
      </visual>
      <collision>
        <origin xyz="0.0 1.2 1.0" rpy="1.5708 0.0 0.0"/>
        <geometry>
          <cylinder radius="0.5" length="2"/>
        </geometry>
      </collision>
    </link>

    <!-- Fixed joint attaching the shaft to the robot base -->
    <joint name="base_joint_${id}" type="fixed">
      <origin xyz="${x} ${y} 0.0" rpy="0.0 0.0 ${rpy}"/>
      <parent link="center_link"/>
      <child link="shaft_link_${id}"/>
    </joint>

    <!-- Wheel Link -->
    <link name="wheel_link_${id}">
      <inertial>
        <origin xyz="0.0 0.0 0.0" rpy="0.0 0.0 0.0"/>
        <mass value="0.5"/>
        <inertia ixx="0.5" ixy="0.0" ixz="0.0" iyy="0.25" iyz="0.0" izz="0.5"/>
      </inertial>
      <visual>
        <origin xyz="0.0 0.0 -0.2" rpy="0.0 0.0 0.0"/>
        <geometry>
          <cylinder radius="1.0" length="0.3"/>
        </geometry>
        <material name="black">
          <color rgba="0.0 0.0 0.0 1.0"/>
        </material>
      </visual>
      <surface>
        <friction>
          <ode>
            <mu>100</mu>
            <mu2>100</mu2>
          </ode>
        </friction>
        <contact>
          <ode>
            <min_depth>0.003</min_depth>
          </ode>
        </contact>
      </surface>
      <collision>
        <origin xyz="0.0 0.0 0.0" rpy="0.0 0.0 0.0"/>
        <geometry>
          <cylinder radius="1.0" length="0.3"/>
        </geometry>
      </collision>
    </link>

    <!-- Continuous joint connecting the shaft to the wheel, with embedded FT sensor -->
    <joint name="wheel_joint_${id}" type="continuous">
      <origin xyz="0.0 2.0 1.0" rpy="1.57 0.0 0.0"/>
      <parent link="shaft_link_${id}"/>
      <child link="wheel_link_${id}"/>
      <axis xyz="0.0 0.0 1.0"/>
      <limit effort="10.0" velocity="5.0"/>
    <provideFeedback>true</provideFeedback>
      <physics>
            <provideFeedback>true</provideFeedback>
        </physics>
      <gazebo>
            <physics>
            <provideFeedback>true</provideFeedback>
            </physics>
            <provideFeedback>true</provideFeedback>
        <sensor type="force_torque" name="ft_sensor_wheel_${id}">
          <always_on>true</always_on>
          <update_rate>100</update_rate>
          <force_torque>
            <frame>child</frame>
          </force_torque>
        </sensor>
      </gazebo>
    </joint>

    <!-- Transmission referencing the continuous joint -->
    <transmission name="wheel_joint_transmission_${id}">
      <type>transmission_interface/SimpleTransmission</type>
      <joint name="wheel_joint_${id}">
        <hardwareInterface>hardware_interface/EffortJointInterface</hardwareInterface>
      </joint>
      <actuator name="wheel_motor_${id}">
        <hardwareInterface>hardware_interface/EffortJointInterface</hardwareInterface>
        <mechanicalReduction>1</mechanicalReduction>
      </actuator>
    </transmission>
    <gazebo reference="wheel_joint_${id}">
        <provideFeedback>true</provideFeedback>
    </gazebo>
  </xacro:macro>

  <!-- Instantiate three shaft/wheel assemblies at 0°, +120°, -120° -->
  <xacro:property name="r" value="-1"/>
  <!-- Angles in radians -->
  <xacro:property name="theta1" value="0.0"/>
  <xacro:property name="theta2" value="2.0943951"/>    <!-- 120 deg -->
  <xacro:property name="theta3" value="-2.0943951"/>   <!-- -120 deg -->
  <!-- Additional rotation if needed -->
  <xacro:property name="rotate90" value="1.5708"/>

  <xacro:shaft_wheel
      id="1"
      x="${r * cos(theta1)}"
      y="${r * sin(theta1)}"
      rpy="${theta1 + rotate90}"
  />
  <xacro:shaft_wheel
      id="2"
      x="${r * cos(theta2)}"
      y="${r * sin(theta2)}"
      rpy="${theta2 + rotate90}"
  />
  <xacro:shaft_wheel
      id="3"
      x="${r * cos(theta3)}"
      y="${r * sin(theta3)}"
      rpy="${theta3 + rotate90}"
  />



  <gazebo>
      <provideFeedback>true</provideFeedback>
    <plugin name="gazebo_ros_control" filename="libgazebo_ros_control.so">
      <robotNamespace>/trikey_light</robotNamespace>
    </plugin>


    <!-- ros-noetic-gazebo-plugins -->


    <!-- FT sensor plugin for wheel 1 -->
    <plugin name="ft_sensor_plugin_1" filename="libgazebo_ros_ft_sensor.so">
      <ros>
        <namespace>/trikey_light</namespace>
        <remapping>~/ft : ft_sensor_1</remapping>
      </ros>
      <update_rate>100</update_rate>
      <bodyName>wheel_link_1</bodyName>
      <jointName>wheel_joint_1</jointName>
      <sensorName>ft_sensor_wheel_1</sensorName>
      <topicName>ft_sensor_1_topic</topicName>
    </plugin>

    <!-- FT sensor plugin for wheel 2 -->
    <plugin name="ft_sensor_plugin_2" filename="libgazebo_ros_ft_sensor.so">
      <ros>
        <namespace>/trikey_light</namespace>
        <remapping>~/ft : ft_sensor_2</remapping>
      </ros>
      <update_rate>100</update_rate>
      <bodyName>wheel_link_2</bodyName>
      <jointName>wheel_joint_2</jointName>
      <sensorName>ft_sensor_wheel_2</sensorName>
      <topicName>ft_sensor_2_topic</topicName>
    </plugin>

    <!-- FT sensor plugin for wheel 3 -->
    <plugin name="ft_sensor_plugin_3" filename="libgazebo_ros_ft_sensor.so">
      <ros>
        <namespace>/trikey_light</namespace>
        <remapping>~/ft : ft_sensor_3</remapping>
      </ros>
      <update_rate>100</update_rate>
      <bodyName>wheel_link_3</bodyName>
      <jointName>wheel_joint_3</jointName>
      <sensorName>ft_sensor_wheel_3</sensorName>
      <topicName>ft_sensor_3_topic</topicName>
    </plugin>

  </gazebo>

</robot>